Workbook

Sheet ПК
A1: СН | B1: 5.8856582e+08 | C1: =B1-B2+B3 -> 5.8856582e+08 | D1: =C1-C2+C3 -> 5.8856582e+08 | E1: =D1-D2+D3 -> 5.8856582e+08 | F1: =E1-E2+E3 -> 5.8856582e+08 | G1: =F1-F2+F3 -> 5.8470582e+08 | H1: =G1-G2+G3 -> 5.8470582e+08 | I1: =H1-H2+H3 -> 5.8470582e+08 | J1: =I1-I2+I3 -> 5.195991e+08 | ... AF1: =AE1-AE2+AE3 -> 694576729
A2: РАСХОД | B2: =B40 -> 0 | C2: =C40 -> 0 | D2: =D40 -> 0 | E2: =E40 -> 0 | F2: =F40 -> 3860000 | G2: =G40 -> 0 | H2: =H40 -> 0 | I2: =I40 -> 65106723 | ... AF2: =AF40 -> 774956952 | AG2: =SUM(B2:AF2) -> 9.9186186e+08
A3: ПОСТУПЛЕНИЯ | B3: =B50 -> 0 | C3: =C50 -> 0 | D3: =D50 -> 0 | E3: =E50 -> 0 | F3: =F50 -> 0 | G3: =G50 -> 0 | H3: =H50 -> 0 | I3: =I50 -> 0 | ... AF3: =AF50 -> 1110300000 | AG3: =SUM(B3:AF3) -> 1433215812
A4: СК | B4: =B1-B2+B3 -> 5.8856582e+08 | C4: =C1-C2+C3 -> 5.8856582e+08 | D4: =D1-D2+D3 -> 5.8856582e+08 | E4: =E1-E2+E3 -> 5.8856582e+08 | F4: =F1-F2+F3 -> 5.8470582e+08 | G4: =G1-G2+G3 -> 5.8470582e+08 | H4: =H1-H2+H3 -> 5.8470582e+08 | I4: =I1-I2+I3 -> 5.195991e+08 | ... AF4: =AF1-AF2+AF3 -> 1029919777 | AG4: =AG3-AG2 -> 4.4135396e+08
B6: 46143 | C6: 46144 | D6: 46145 | E6: 46146 | F6: 46147 | G6: 46148 | H6: 46149 | I6: 46150 | J6: 46151 | K6: 46152 | L6: 46153 | M6: 46154 | N6: 46155 | O6: 46156 | P6: 46157 | Q6: 46158 | R6: 46159 | S6: 46160 | T6: 46161 | U6: 46162 | V6: 46163 | W6: 46164 | X6: 46165 | Y6: 46166 | Z6: 46167 | AA6: 46168 | AB6: 46169 | AC6: 46170 | AD6: 46171 | AE6: 46172 | AF6: 46173
A7: РАСХОДНАЯ часть
A8: Зарплата | K8: 3155000
A9: Аванс
A10: налоги:
A11: НДФЛ | P11: 426642.04
A12: НДФЛ у источника выплат | P12: 1430727.2
A13: ИНПС | P13: 3585.23
A14: Соц., платеж | P14: 430227.27
Q15: .
A16: НДС | U16: 125600000
A17: НДС (импорт услуг) | U17: 6400000
A19: Прибыль
A20: Доход нерезидента
A22: Административные:
A24: Аренда офиса | AD24: 10492000
A25: Возмещение расходов (аренда) | F25: 500000
A26: Бухгалтерское соправождение | F26: 3360000
A27: Связь
A28: Интернет
A30: резерв (БИРЖА)
A32: доп., заявки на расход | B32: ='доп., заявки на расход'!H46 -> 0 | C32: ='доп., заявки на расход'!I46 -> 0 | D32: ='доп., заявки на расход'!J46 -> 0 | E32: ='доп., заявки на расход'!K46 -> 0 | F32: ='доп., заявки на расход'!L46 -> 0 | G32: ='доп., заявки на расход'!M46 -> 0 | H32: ='доп., заявки на расход'!N46 -> 0 | I32: ='доп., заявки на расход'!O46 -> 0 | ... AF32: ='доп., заявки на расход'!AL46 -> 0
A34: Товары для отгрузки по договорам
A35: Расход АДМИН | B35: =SUM(B7:B34) -> 0 | C35: =SUM(C7:C34) -> 0 | D35: =SUM(D7:D34) -> 0 | E35: =SUM(E7:E34) -> 0 | F35: =SUM(F7:F34) -> 3860000 | G35: =SUM(G7:G34) -> 0 | H35: =SUM(H7:H34) -> 0 | I35: =SUM(I7:I34) -> 0 | ... AF35: =SUM(AF7:AF34) -> 0 | AG35: =SUM(B35:AF35) -> 1.5179818e+08
A37: Прогноз расходов Артём | B37: ='прогн. Артём'!I78 -> 0 | C37: ='прогн. Артём'!J78 -> 0 | D37: ='прогн. Артём'!K78 -> 0 | E37: ='прогн. Артём'!L78 -> 0 | F37: ='прогн. Артём'!M78 -> 0 | G37: ='прогн. Артём'!N78 -> 0 | H37: ='прогн. Артём'!O78 -> 0 | I37: ='прогн. Артём'!P78 -> 0 | ... AF37: ='прогн. Артём'!AM78 -> 0 | AG37: =SUM(B37:AF37) -> 0
A38: Прогноз расходов Алина | B38: ='прогн. Алина'!I78 -> 0 | C38: ='прогн. Алина'!J78 -> 0 | D38: ='прогн. Алина'!K78 -> 0 | E38: ='прогн. Алина'!L78 -> 0 | F38: ='прогн. Алина'!M78 -> 0 | G38: ='прогн. Алина'!N78 -> 0 | H38: ='прогн. Алина'!O78 -> 0 | I38: ='прогн. Алина'!P78 -> 65106723 | ... AF38: ='прогн. Алина'!AM78 -> 774956952 | AG38: =SUM(B38:AF38) -> 840063675
A40: РАСХОД всего: | B40: =B35+B37+B38 -> 0 | C40: =C35+C37+C38 -> 0 | D40: =D35+D37+D38 -> 0 | E40: =E35+E37+E38 -> 0 | F40: =F35+F37+F38 -> 3860000 | G40: =G35+G37+G38 -> 0 | H40: =H35+H37+H38 -> 0 | I40: =I35+I37+I38 -> 65106723 | ... AF40: =AF35+AF37+AF38 -> 774956952 | AG40: =SUM(B40:AF40) -> 9.9186186e+08
A44: ПОСТУПЛЕНИЯ
A46: Прогноз продаж Артём | B46: ='прогн. Артём'!I36 -> 0 | C46: ='прогн. Артём'!J36 -> 0 | D46: ='прогн. Артём'!K36 -> 0 | E46: ='прогн. Артём'!L36 -> 0 | F46: ='прогн. Артём'!M36 -> 0 | G46: ='прогн. Артём'!N36 -> 0 | H46: ='прогн. Артём'!O36 -> 0 | I46: ='прогн. Артём'!P36 -> 0 | ... AF46: ='прогн. Артём'!AM36 -> 0 | AG46: =SUM(B46:AF46) -> 0
A47: Прогноз продаж Алина | B47: ='прогн. Алина'!I36 -> 0 | C47: ='прогн. Алина'!J36 -> 0 | D47: ='прогн. Алина'!K36 -> 0 | E47: ='прогн. Алина'!L36 -> 0 | F47: ='прогн. Алина'!M36 -> 0 | G47: ='прогн. Алина'!N36 -> 0 | H47: ='прогн. Алина'!O36 -> 0 | I47: ='прогн. Алина'!P36 -> 0 | ... AF47: ='прогн. Алина'!AM36 -> 1110300000 | AG47: =SUM(B47:AF47) -> 1433215812
A48: Прочие поступления не являющиеся доходами | B48: ='прогн. Артём'!I39+'прогн. Алина'!I39 -> 0 | C48: ='прогн. Артём'!J39+'прогн. Алина'!J39 -> 0 | D48: ='прогн. Артём'!K39+'прогн. Алина'!K39 -> 0 | E48: ='прогн. Артём'!L39+'прогн. Алина'!L39 -> 0 | F48: ='прогн. Артём'!M39+'прогн. Алина'!M39 -> 0 | G48: ='прогн. Артём'!N39+'прогн. Алина'!N39 -> 0 | H48: ='прогн. Артём'!O39+'прогн. Алина'!O39 -> 0 | I48: ='прогн. Артём'!P39+'прогн. Алина'!P39 -> 0 | ... AF48: ='прогн. Артём'!AM39+'прогн. Алина'!AM39 -> 0
A50: ПОСТУПЛЕНИЯ всего: | B50: =SUM(B46:B48) -> 0 | C50: =SUM(C46:C48) -> 0 | D50: =SUM(D46:D48) -> 0 | E50: =SUM(E46:E48) -> 0 | F50: =SUM(F46:F48) -> 0 | G50: =SUM(G46:G48) -> 0 | H50: =SUM(H46:H48) -> 0 | I50: =SUM(I46:I48) -> 0 | ... AF50: =SUM(AF46:AF48) -> 1110300000 | AG50: =SUM(B50:AF50) -> 1433215812
A54: СВОД показателей:
A56: Всего РАСХОД: | B56: =B58+B60 -> 9.9186186e+08
A57: из них
A58: Административный | B58: =AG35 -> 1.5179818e+08
...

Sheet прогн. Артём
B1: OOO RAHAT NETWORKS
B3: ПРОДАЖИ прогноз на | C3: Май 2026 года
A5: № | B5: Компания покупатель | C5: ИНН | D5: Контракт | E5: предоплата/оплата | F5: Сумма | G5: Эквив-т в валюте | I5: Дата поступления
B6: Договора на обслуживание (постоянные) | I6: 46143 | J6: 46144 | K6: 46145 | L6: 46146 | M6: 46147 | N6: 46148 | O6: 46149 | P6: 46150 | Q6: 46151 | R6: 46152 | S6: 46153 | T6: 46154 | U6: 46155 | V6: 46156 | W6: 46157 | X6: 46158 | Y6: 46159 | Z6: 46160 | AA6: 46161 | AB6: 46162 | AC6: 46163 | AD6: 46164 | AE6: 46165 | AF6: 46166 | AG6: 46167 | AH6: 46168 | AI6: 46169 | AJ6: 46170 | AK6: 46171 | AL6: 46172 | AM6: 46173
B7: Uztelecom | C7: 203 366 731 | D7: WNAM-2026-S
A16: ИТОГО: | F16: =SUM(F7:F15) -> 0 | G16: =SUM(G7:G15) -> 0
A17: Контракты проектные
A26: ИТОГО: | F26: =SUM(F18:F25) -> 0 | G26: =SUM(G18:G25) -> 0
A27: Прочие разовые договора
A35: ИТОГО: | F35: =SUM(F28:F34) -> 0 | G35: =SUM(G28:G34) -> 0
A36: ИТОГО поступлений: | F36: =F16+F26+F35 -> 0 | G36: =G16+G26+G35 -> 0 | I36: =SUM(I7:I35) -> 0 | J36: =SUM(J7:J35) -> 0 | K36: =SUM(K7:K35) -> 0 | L36: =SUM(L7:L35) -> 0 | M36: =SUM(M7:M35) -> 0 | N36: =SUM(N7:N35) -> 0 | O36: =SUM(O7:O35) -> 0 | P36: =SUM(P7:P35) -> 0 | ... AM36: =SUM(AM7:AM35) -> 0
B38: Прочие поступления не являющиеся доходами
B39: Возврат средств от БИРЖИ | E39: был внесен депозип | F39: 110000000
A44: Заполняются данные о приобретаемом оборудовании, лицензиях и прочих составляющих для исполнения контракта по продаже
A45: Обязательства по сделке
A47: № | B47: Компания поставщик | C47: ИНН | D47: Контракт | E47: Суть (контр с покуп) | F47: Сумма | G47: Эквив-т в валюте | I47: Дата списания
B48: Договора на обслуживание (постоянные)
A58: ИТОГО: | F58: =SUM(F49:F57) -> 0 | G58: =SUM(G49:G57) -> 0
B59: Контракты проектные
A68: ИТОГО: | F68: =SUM(F60:F67) -> 0 | G68: =SUM(G60:G67) -> 0
B69: Прочие разовые договора
F73: =Q73 | G73: =R73
A77: ИТОГО: | F77: =SUM(F70:F76) -> 0 | G77: =SUM(G70:G76) -> 0
A78: ИТОГО расходов: | F78: =F58+F68+F77 -> 0 | G78: =G58+G68+G77 -> 0 | I78: =SUM(I48:I77) -> 0 | J78: =SUM(J48:J77) -> 0 | K78: =SUM(K48:K77) -> 0 | L78: =SUM(L48:L77) -> 0 | M78: =SUM(M48:M77) -> 0 | N78: =SUM(N48:N77) -> 0 | O78: =SUM(O48:O77) -> 0 | P78: =SUM(P48:P77) -> 0 | ... AM78: =SUM(AM48:AM77) -> 0

Sheet прогн. Алина
B1: OOO RAHAT NETWORKS
B3: ПРОДАЖИ прогноз на | C3: Май 2026 года
A5: № | B5: Компания покупатель | C5: ИНН | D5: предоплата/оплата | E5: Контракт | F5: Сумма | G5: Эквив-т в валюте | I5: Дата поступления
A6: Договора на обслуживание (постоянные) | I6: 46143 | J6: 46144 | K6: 46145 | L6: 46146 | M6: 46147 | N6: 46148 | O6: 46149 | P6: 46150 | Q6: 46151 | R6: 46152 | S6: 46153 | T6: 46154 | U6: 46155 | V6: 46156 | W6: 46157 | X6: 46158 | Y6: 46159 | Z6: 46160 | AA6: 46161 | AB6: 46162 | AC6: 46163 | AD6: 46164 | AE6: 46165 | AF6: 46166 | AG6: 46167 | AH6: 46168 | AI6: 46169 | AJ6: 46170 | AK6: 46171 | AL6: 46172 | AM6: 46173
P7: =F7
A16: ИТОГО: | F16: =SUM(F6:F15) -> 0 | G16: =SUM(G6:G15) -> 0
A17: Контракты проектные
O19: =F19
B20: АО "CLICK" | C20: 302 134 733 | D20: 0 | E20: CLICK-LAN-2026-5 от 14.04.2026г. | F20: 236120510 | W20: 236120510
B21: IMKON SUG'URTA | F21: 81800000 | AM21: 81800000
B22: ANOR BANK | F22: =G22*12100 -> 1028500000 | G22: 85000 | AM22: 1028500000
B23: Центр цифровизации и монитоинга водного хозяйства | C23: 202 355 801 | D23: 0 | E23: №4421841 от 30.04.2026 | F23: 86795302 | W23: 86795302
A26: ИТОГО: | F26: =SUM(F18:F25) -> 1433215812 | G26: =SUM(G18:G25) -> 85000
A27: Прочие разовые договора
A35: ИТОГО: | F35: =SUM(F28:F34) -> 0 | G35: =SUM(G28:G34) -> 0
A36: ИТОГО поступлений: | F36: =F16+F26+F35 -> 1433215812 | G36: =G16+G26+G35 -> 85000 | I36: =SUM(I7:I35) -> 0 | J36: =SUM(J7:J35) -> 0 | K36: =SUM(K7:K35) -> 0 | L36: =SUM(L7:L35) -> 0 | M36: =SUM(M7:M35) -> 0 | N36: =SUM(N7:N35) -> 0 | O36: =SUM(O7:O35) -> 0 | P36: =SUM(P7:P35) -> 0 | ... AM36: =SUM(AM7:AM35) -> 1110300000
B38: Прочие поступления не являющиеся доходами
B39: Возврат средств от БИРЖИ | E39: был внесен депозип
A44: Заполняются данные о приобретаемом оборудовании, лицензиях и прочих составляющих для исполнения контракта по продаже
A45: Обязательства по сделке
A47: № | B47: Компания поставщик | C47: ИНН | D47: Контракт | E47: Суть (контр с покуп) | F47: Сумма | G47: Эквив-т в валюте | I47: Дата списания
B48: Договора на обслуживание (постоянные)
A58: ИТОГО: | F58: =SUM(F49:F57) -> 0 | G58: =SUM(G49:G57) -> 0
B59: Контракты проектные
M61: =F61
B62: MIGHTYFALCON FZCO | D62: № 0020250929 от 29.09.2025 | E62: Поставка лицензии для FortiGate-120G (Водное хозяйство) | F62: =G62*12200 -> 36587800 | G62: 2999 | AM62: 36587800
B63: MIGHTYFALCON FZCO | E63: Поставка FortiGate-120G( Водное хозяйство) | F63: 21702241 | P63: 21702241
B64: ООО "AXOFT" | C64: 308483374 | D64: AF26-002 от 13.01.2026 | E64: Поставка лицензий ESET (Imkon Sug'urta) | F64: 61952352 | AM64: 61952352
B65: MIGHTYFALCON FZCO | D65: № 0020250929 от 29.09.2025 | E65: Поставка лицензии для FortiGate-120G (CLICK) | F65: =G65*12200 -> 116485600 | G65: 9548 | AM65: 116485600
B66: MIGHTYFALCON FZCO | E66: Поставка FortiGate-120G (CLICK) | F66: 43404482 | P66: 43404482
B67: IITD | E67: Поставка CDK (ANOR BANK) | F67: =G67*12200 -> 559931200 | G67: 45896 | AM67: 559931200
A68: ИТОГО: | F68: =SUM(F60:F67) -> 840063675 | G68: =SUM(G60:G67) -> 58443
B69: Прочие разовые договора
F73: =Q73 | G73: =R73
A77: ИТОГО: | F77: =SUM(F70:F76) -> 0 | G77: =SUM(G70:G76) -> 0
A78: ИТОГО расходов: | F78: =F58+F68+F77 -> 840063675 | G78: =G58+G68+G77 -> 58443 | I78: =SUM(I48:I77) -> 0 | J78: =SUM(J48:J77) -> 0 | K78: =SUM(K48:K77) -> 0 | L78: =SUM(L48:L77) -> 0 | M78: =SUM(M48:M77) -> 0 | N78: =SUM(N48:N77) -> 0 | O78: =SUM(O48:O77) -> 0 | P78: =SUM(P48:P77) -> 65106723 | ... AM78: =SUM(AM48:AM77) -> 774956952
B86: 3715410000 | C86: =B86*12/112 -> 3.9807964e+08 | E86: =B86-C86 -> 3317330357
B88: 3312805584 | C88: =B88*12/112 -> 3.5494346e+08 | D88: =B88+B89 -> 3379055824 | E88: =E86-D88 -> -61725467
B89: 66250240 | C89: =B89*12/112 -> 7098240
C90: =SUM(C88:C89) -> 3.620417e+08
...

Sheet доп., заявки на расход
B1: OOO RAHAT NETWORKS
B3: План РАСХОДОВ на | C3: Май 2026 года
A5: № | B5: Предмет | C5: Контрагент | D5: Основание | E5: Дата | F5: Сумма | H5: 46143 | I5: 46144 | J5: 46145 | K5: 46146 | L5: 46147 | M5: 46148 | N5: 46149 | O5: 46150 | P5: 46151 | Q5: 46152 | R5: 46153 | S5: 46154 | T5: 46155 | U5: 46156 | V5: 46157 | W5: 46158 | X5: 46159 | Y5: 46160 | Z5: 46161 | AA5: 46162 | AB5: 46163 | AC5: 46164 | AD5: 46165 | AE5: 46166 | AF5: 46167 | AG5: 46168 | AH5: 46169 | AI5: 46170 | AJ5: 46171 | AK5: 46172 | AL5: 46173
O6: =E6
N18: =E18
E46: ИТОГО: | F46: =SUM(F6:F45) -> 0 | H46: =SUM(H6:H45) -> 0 | I46: =SUM(I6:I45) -> 0 | J46: =SUM(J6:J45) -> 0 | K46: =SUM(K6:K45) -> 0 | L46: =SUM(L6:L45) -> 0 | M46: =SUM(M6:M45) -> 0 | N46: =SUM(N6:N45) -> 0 | O46: =SUM(O6:O45) -> 0 | ... AL46: =SUM(AL6:AL45) -> 0

Sheet Выписки
A1: № пп | B1: Дата документа | C1: № док | D1: Наименование счёта | E1: ИНН | F1: № счёта | G1: МФО | H1: Обороты по кредиту | I1: Назначение платежа
A2: 1 | B2: 46140 | C2: 2076538 | D2: "CLICK" AJ | E2: 302134733 | F2: 29896000804942713020 | G2: 401 | H2: 3 312,40 | I2: П/О, ОПЛАТА ЗА ТОВАРЫ, УСЛУГИ ЗА 27.04.2026 ПО СЕРВИСУ №96558 ОПЛАТА ЗА УСЛУГИ ITD.UZ CОГ-НО ДОГ.№B/D 27290\TASH ОТ 2026-02-06 ЧЕРЕЗ CLICK. СУММА ПРОДАЖ 3380.00 СУМ. УДЕРЖАНО ОТ СУММЫ ПЛАТЕЖА: -КОМИССИЯ С ПЛАТЕЖА 67.60 СУМ; . (№2076538, ОБЩ. СУММА 3312.4 UZS, ОТ 28.04.2026Г.)
A3: 2 | B3: 46141 | C3: 2091232 | D3: "CLICK" AJ | E3: 302134733 | F3: 29896000804942713020 | G3: 401 | H3: 980 | I3: П/О, ОПЛАТА ЗА ТОВАРЫ, УСЛУГИ ЗА 28.04.2026 ПО СЕРВИСУ №96558 ОПЛАТА ЗА УСЛУГИ ITD.UZ CОГ-НО ДОГ.№B/D 27290\TASH ОТ 2026-02-06 ЧЕРЕЗ CLICK. СУММА ПРОДАЖ 1000.00 СУМ. УДЕРЖАНО ОТ СУММЫ ПЛАТЕЖА: -КОМИССИЯ С ПЛАТЕЖА 20.00 СУМ; . (№2091232, ОБЩ. СУММА 980 UZS, ОТ 29.04.2026Г.)
A4: 3 | B4: 46141 | C4: 370456534 | D4: Начисленные %% ООО "RAHAT NETWORKS" | E4: 308483374 | F4: 16401000805393478001 | G4: 445 | H4: 0 | I4: За документ №62 S=3 312 805 584,00 Тариф-ТАРИФ "CORPORATE"-1 000,00 UZS.в том числе НДС
A5: 4 | B5: 46141 | C5: 4650071 | D5: Иктисодиёт ва молия вазирлиги Ягона газна хисобвараги | E5: 201122919 | F5: 23402000300100001010 | G5: 14 | H5: 3 715 410 000,00 | I5: 700110860262877950600262008~200933985~За Оборудование компьютерное, электронное и оптическое, договор №4259274 от 19.03.2026 от ИНН: 305907639("KIBERXAVFSIZLIK MARKAZI" DUK) xarid.uzex.uz (Электронный магазин)
A6: 5 | B6: 46141 | C6: 62 | D6: "AXOFT" MCHJ | E6: 305774212 | F6: 20208000500924989001 | G6: 974 | H6: 0 | I6: 00668 Оплата передачи неисключительного права использования согласно договору № AF26-002 от 13.01.2026.
A7: 6 | B7: 46142 | C7: 383312988 | D7: Начисленные %% ООО "RAHAT NETWORKS" | E7: 308483374 | F7: 16401000805393478001 | G7: 445 | H7: 0 | I7: За документ №63 S=3 360 000,00 Тариф-ТАРИФ "CORPORATE"-1 000,00 UZS.в том числе НДС
A8: 7 | B8: 46142 | C8: 63 | D8: OOO "PROSTEP" | E8: 308455582 | F8: 20208000605388834001 | G8: 445 | H8: 0 | I8: 00668 Бухгалтерские услуги за апрель месяц 2026г.
A9: 8 | D9: Итого за весь период | G9: 3 715 414 292,40 | I9: Входящее сальдо: 89,812,112.70. Исходящее сальдо: 489,058,821.10
